{
  "contest": 302,
  "handle": "t0x1c",
  "risk": "3",
  "title": "If transfer of funds fails due to any reason inside `claimAuction()`, they can't be claimed again",
  "issueId": 708,
  "issueUrl": "https://github.com/code-423n4/2023-10-nextgen-findings/issues/708"
}